Workbook

Sheet Calculation
A8: Cable and Wire Bundle Calculator To compute the bundle diameter, enter in the number of wires or cables used in the cable run. The results are computes and posed to E39 | I8: Shrink Sleeving Ranges. GREEN Boxes indicated that the MAX or MIN values are within the range of the Computed Bundle Diameter in E39. To choose an acceptable shrink sleeving, for a given row the MIN and the MAX must be GREEN. | Q8: Tubular Braid Ranges. GREEN Boxes indicated that nominal diameter is within the range of the Computed Bundle Diameter in E39. Pick the nearest size smaller than the diameter and add additional length to BOM qty to account for sleeving expansion.
A10: Wire/Cable Material | B10: Wire Diameter (inches) | C10: Number of Wires/Cables In Bundle | D10: Intermediate Avg Wire Dia | E10: Bundle Diameter of a bundle with material of same size (inches) | I10: M23053/13-xxx-0 Shrink Sleeving | J10: Max | K10: Min | L10: Wall Thickness | M10: M23053/16-xxx-0 Heavy Duty Shink Sleeving | N10: Max | O10: Min | P10: Wall Thickness | Q10: AA59569RxxTyyy Tubular Braid | R10: AWG | S10: Inside Diameter (inches) | T10: GRP-110NFXXX Snakeskin Sleeving | U10: VICD Number | V10: Max | W10: Min | X10: Wall Thickness | Y10: M23053/5-xxx-9 Labels | Z10: Max | AA10: Min | AB10: Wall Thickness
A11: Hook Up Wire | I11: -012 | J11: 0.125 | K11: 0.062 | L11: 0.03 | M11: -001 | N11: 0.25 | O11: 0.125 | P11: 0.035 | Q11: AA59569R36T0031 | R11: 36 | S11: 0.031 | T11: GRP-110NF18 | U11: 10111656-001 | V11: 0.25 | W11: 0.125 | X11: 0.024 | Y11: -101 | Z11: 0.046 | AA11: 0.023 | AB11: 0.016
A12: M22758/11-8-x | B12: 0.202 | C12: 0 | D12: =C12*B12 -> 0 | E12: =B12*LOOKUP(C12,'Bundle Factors'!$A$2:$A$301,'Bundle Factors'!$C$2:$C$301) -> #N/A | I12: -001 | J12: 0.187 | K12: 0.093 | L12: 0.035 | M12: -002 | N12: 0.375 | O12: 0.187 | P12: 0.04 | Q12: AA59569R36T0062 | R12: 36 | S12: 0.062 | T12: GRP-110NF14 | U12: 10111656-002 | V12: 0.438 | W12: 0.156 | X12: 0.024 | Y12: -102 | Z12: 0.063 | AA12: 0.031 | AB12: 0.017
A13: M22758/11-10-x | B13: 0.139 | C13: 0 | D13: =C13*B13 -> 0 | E13: =B13*LOOKUP(C13,'Bundle Factors'!$A$2:$A$301,'Bundle Factors'!$C$2:$C$301) -> #N/A | I13: -002 | J13: 0.25 | K13: 0.125 | L13: 0.035 | M13: -003 | N13: 0.5 | O13: 0.25 | P13: 0.048 | Q13: AA59569R34T0062 | R13: 34 | S13: 0.062 | T13: GRP-110NF12 | U13: 10111656-003 | V13: 0.75 | W13: 0.25 | X13: 0.024 | Y13: -103 | Z13: 0.093 | AA13: 0.046 | AB13: 0.02
A14: M22758/11-12-x | B14: 0.111 | C14: 0 | D14: =C14*B14 -> 0 | E14: =B14*LOOKUP(C14,'Bundle Factors'!$A$2:$A$301,'Bundle Factors'!$C$2:$C$301) -> #N/A | I14: -003 | J14: 0.375 | K14: 0.187 | L14: 0.035 | M14: -004 | N14: 0.748 | O14: 0.375 | P14: 0.057 | Q14: AA59569R36T0078 | R14: 36 | S14: 0.078 | T14: GRP-110NF34 | U14: 10111656-004 | V14: 1 | W14: 0.625 | X14: 0.024 | Y14: -104 | Z14: 0.125 | AA14: 0.062 | AB14: 0.02
A15: M22758/11-14-x | B15: 0.09 | C15: 0 | D15: =C15*B15 -> 0 | E15: =B15*LOOKUP(C15,'Bundle Factors'!$A$2:$A$301,'Bundle Factors'!$C$2:$C$301) -> #N/A | I15: -004 | J15: 0.5 | K15: 0.25 | L15: 0.035 | M15: -005 | N15: 1 | O15: 0.5 | P15: 0.07 | Q15: AA59569R36T0109 | R15: 36 | S15: 0.109 | T15: GRP-110NF114 | U15: 10111656-005 | V15: 1.5 | W15: 1 | X15: 0.024 | Y15: -105 | Z15: 0.187 | AA15: 0.093 | AB15: 0.025
A16: M22758/11-16-x | B16: 0.075 | D16: =C16*B16 -> 0 | E16: =B16*LOOKUP(C16,'Bundle Factors'!$A$2:$A$301,'Bundle Factors'!$C$2:$C$301) -> #N/A | I16: -005 | J16: 0.625 | K16: 0.312 | L16: 0.042 | M16: -006 | N16: 1.5 | O16: 0.75 | P16: 0.095 | Q16: AA59569R36T0125 | R16: 36 | S16: 0.125 | T16: GRP-110NF112 | U16: 10111656-006 | V16: 2 | W16: 1.25 | X16: 0.024 | Y16: -106 | Z16: 0.25 | AA16: 0.125 | AB16: 0.025
A17: M22758/11-18-x | B17: 0.068 | C17: 0 | D17: =C17*B17 -> 0 | E17: =B17*LOOKUP(C17,'Bundle Factors'!$A$2:$A$301,'Bundle Factors'!$C$2:$C$301) -> #N/A | I17: -006 | J17: 0.75 | K17: 0.375 | L17: 0.042 | M17: -007 | N17: 2 | O17: 1 | P17: 0.11 | Q17: AA59569R34T0125 | R17: 34 | S17: 0.125 | Y17: -107 | Z17: 0.375 | AA17: 0.187 | AB17: 0.025
A18: M22758/11-20-x | B18: 0.058 | D18: =C18*B18 -> 0 | E18: =B18*LOOKUP(C18,'Bundle Factors'!$A$2:$A$301,'Bundle Factors'!$C$2:$C$301) -> #N/A | I18: -007 | J18: 0.875 | K18: 0.437 | L18: 0.049 | M18: -008 | N18: 3 | O18: 1.5 | P18: 0.125 | Q18: AA59569R36T0156 | R18: 36 | S18: 0.156 | Y18: -108 | Z18: 0.5 | AA18: 0.25 | AB18: 0.03
A19: M22758/11-22-x | B19: 0.049 | C19: 0 | D19: =C19*B19 -> 0 | E19: =B19*LOOKUP(C19,'Bundle Factors'!$A$2:$A$301,'Bundle Factors'!$C$2:$C$301) -> #N/A | I19: -008 | J19: 1 | K19: 0.5 | L19: 0.049 | M19: -009 | N19: 4 | O19: 2 | P19: 0.14 | Q19: AA59569R36T0171 | R19: 36 | S19: 0.171 | Y19: -109 | Z19: 0.75 | AA19: 0.375 | AB19: 0.035
A20: M22758/11-24-x | B20: 0.043 | D20: =C20*B20 -> 0 | E20: =B20*LOOKUP(C20,'Bundle Factors'!$A$2:$A$301,'Bundle Factors'!$C$2:$C$301) -> #N/A | I20: -009 | J20: 1.25 | K20: 0.625 | L20: 0.055 | Q20: AA59569R34T0171 | R20: 34 | S20: 0.171 | Y20: -110 | Z20: 1 | AA20: 0.5 | AB20: 0.04
A21: M22758/11-26-x | B21: 0.038 | D21: =C21*B21 -> 0 | E21: =B21*LOOKUP(C21,'Bundle Factors'!$A$2:$A$301,'Bundle Factors'!$C$2:$C$301) -> #N/A | I21: -010 | J21: 1.5 | K21: 0.75 | L21: 0.055 | Q21: AA59569R36T0203 | R21: 36 | S21: 0.203 | Y21: -111 | Z21: 1.5 | AA21: 0.75 | AB21: 0.045
A22: M22758/11-28-x | B22: 0.033 | D22: =C22*B22 -> 0 | E22: =B22*LOOKUP(C22,'Bundle Factors'!$A$2:$A$301,'Bundle Factors'!$C$2:$C$301) -> #N/A | I22: -011 | J22: 2 | K22: 1 | L22: 0.062 | Q22: AA59569R34T0203 | R22: 34 | S22: 0.203 | Y22: -112 | Z22: 2 | AA22: 1 | AB22: 0.05
A23: insert your wire mat'l here add the wire diameter to >> | D23: =C23*B23 -> 0 | E23: =B23*LOOKUP(C23,'Bundle Factors'!$A$2:$A$301,'Bundle Factors'!$C$2:$C$301) -> #N/A | Q23: AA59569R36T0250 | R23: 36 | S23: 0.25 | Y23: -113 | Z23: 3 | AA23: 1.5 | AB23: 0.055
A24: Cable | Q24: AA59569R30T0281 | R24: 30 | S24: 0.281 | Y24: -114 | Z24: 4 | AA24: 2 | AB24: 0.045
A25: M27500-8RC2S06 | B25: 0.5 | D25: =C25*B25 -> 0 | E25: =B25*LOOKUP(C25,'Bundle Factors'!$A$2:$A$301,'Bundle Factors'!$C$2:$C$301) -> #N/A | Q25: AA59569R36T0375 | R25: 36 | S25: 0.375 | Y25: Overexpanded
A26: M27500-10RC2S06 | B26: 0.348 | D26: =C26*B26 -> 0 | E26: =B26*LOOKUP(C26,'Bundle Factors'!$A$2:$A$301,'Bundle Factors'!$C$2:$C$301) -> #N/A | Q26: AA59569R34T0375 | R26: 34 | S26: 0.375 | Y26: -115 | Z26: 1 | AA26: 0.275 | AB26: 0.045
A27: M27500-12RC2S06 | B27: 0.286 | D27: =C27*B27 -> 0 | E27: =B27*LOOKUP(C27,'Bundle Factors'!$A$2:$A$301,'Bundle Factors'!$C$2:$C$301) -> #N/A | Q27: AA59569R32T0375 | R27: 32 | S27: 0.375 | Y27: -116 | Z27: 2 | AA27: 0.55 | AB27: 0.045
A28: M27500-14RC2S06 | B28: 0.242 | D28: =C28*B28 -> 0 | E28: =B28*LOOKUP(C28,'Bundle Factors'!$A$2:$A$301,'Bundle Factors'!$C$2:$C$301) -> #N/A | Q28: AA59569R30T0437 | R28: 30 | S28: 0.437 | Y28: -117 | Z28: 3 | AA28: 0.81 | AB28: 0.045
A29: M27500-16RC4S06 | B29: 0.221 | D29: =C29*B29 -> 0 | E29: =B29*LOOKUP(C29,'Bundle Factors'!$A$2:$A$301,'Bundle Factors'!$C$2:$C$301) -> #N/A | Q29: AA59569R36T0500 | R29: 36 | S29: 0.5 | Y29: -118 | Z29: 4 | AA29: 1.05 | AB29: 0.045
A30: M27500-16RC3S06 | B30: =AVERAGE(B29,B31) -> 0.2165 | D30: =C30*B30 -> 0 | E30: =B30*LOOKUP(C30,'Bundle Factors'!$A$2:$A$301,'Bundle Factors'!$C$2:$C$301) -> #N/A | Q30: AA59569R34T0500 | R30: 34 | S30: 0.5 | Y30: -119 | Z30: 1 | AA30: 0.462 | AB30: 0.045
A31: M27500-16RC2S06 | B31: 0.212 | D31: =C31*B31 -> 0 | E31: =B31*LOOKUP(C31,'Bundle Factors'!$A$2:$A$301,'Bundle Factors'!$C$2:$C$301) -> #N/A | Q31: AA59569R30T0500 | R31: 30 | S31: 0.5 | Y31: -120 | Z31: 2.375 | AA31: 0.68 | AB31: 0.045
A32: M27500-18RC2S06 | B32: 0.198 | D32: =C32*B32 -> 0 | E32: =B32*LOOKUP(C32,'Bundle Factors'!$A$2:$A$301,'Bundle Factors'!$C$2:$C$301) -> #N/A | Q32: AA59569R30T0562 | R32: 30 | S32: 0.562 | Y32: -121 | Z32: 3 | AA32: 0.84 | AB32: 0.045
A33: M27500-20RC2S06 | B33: 0.178 | D33: =C33*B33 -> 0 | E33: =B33*LOOKUP(C33,'Bundle Factors'!$A$2:$A$301,'Bundle Factors'!$C$2:$C$301) -> #N/A | Q33: AA59569R30T0656 | R33: 30 | S33: 0.656 | Y33: -122 | Z33: 3.75 | AA33: 0.93 | AB33: 0.045
A34: M27500-20RC4S06 | B34: 0.181 | Q34: AA59569R36T0781 | R34: 36 | S34: 0.781 | Y34: -123 | Z34: 4.5 | AA34: 1.45 | AB34: 0.045
A35: M27500-22RC2S06 | B35: 0.16 | D35: =C35*B35 -> 0 | E35: =B35*LOOKUP(C35,'Bundle Factors'!$A$2:$A$301,'Bundle Factors'!$C$2:$C$301) -> #N/A | Q35: AA59569R34T0781 | R35: 34 | S35: 0.781
A36: M27500-24RC2S06 | B36: 0.148 | D36: =C36*B36 -> 0 | E36: =B36*LOOKUP(C36,'Bundle Factors'!$A$2:$A$301,'Bundle Factors'!$C$2:$C$301) -> #N/A | Q36: AA59569R32T0781 | R36: 32 | S36: 0.781
A37: M27500-26RC2S06 | B37: 0.138 | D37: =C37*B37 -> 0 | E37: =B37*LOOKUP(C37,'Bundle Factors'!$A$2:$A$301,'Bundle Factors'!$C$2:$C$301) -> #N/A | Q37: AA59569R30T0875 | R37: 30 | S37: 0.875
A38: M27500-28RC2S06 | B38: 0.128 | D38: =C38*B38 -> 0 | E38: =B38*LOOKUP(C38,'Bundle Factors'!$A$2:$A$301,'Bundle Factors'!$C$2:$C$301) -> #N/A | Q38: AA59569R30T1000 | R38: 30 | S38: 1
A39: M17/176-00002 (TWINAX) | B39: 0.129 | D39: =C39*B39 -> 0 | Q39: AA59569R30T1125 | R39: 30 | S39: 1.125
A40: MX10G-24FLX (Ethernet) | B40: 0.165 | C40: 0 | D40: =C40*B40 -> 0 | E40: =B40*LOOKUP(C40,'Bundle Factors'!$A$2:$A$301,'Bundle Factors'!$C$2:$C$301) -> #N/A | Q40: AA59569R30T1375 | R40: 30 | S40: 1.375
A41: M17/113-RG316 (COAX) | B41: 0.098 | D41: =C41*B41 -> 0 | E41: =B41*LOOKUP(C41,'Bundle Factors'!$A$2:$A$301,'Bundle Factors'!$C$2:$C$301) -> #N/A | Q41: AA59569R30T1500 | R41: 30 | S41: 1.5
L42: Bundle Diameter of a cable + sleeving(inches) | Q42: AA59569R30T2000 | R42: 30 | S42: 2
L43: =E45 -> #DIV/0!
E44: Bundle Diameter of a a mixutre of sized wires (inches)
E45: =SUM(D12:D41)/SUM(C12:C41)*LOOKUP(SUM(C12:C41),'Bundle Factors'!$A$2:$A$301,'Bundle Factors'!$C$2:$C$301) -> #DIV/0!

Sheet Cable Length Calculator
A2: Cable/Branch Length (inches) | C2: FN | D2: # of runs | E2: Add 3" Tolerance and 3% margin | F2: Totalized Quantity w/ margin (Inches) | G2: Totalized Quantity (Feet) Rounded up to nearest 0.5 | H2: Totalized Quantity (Feet) Rounded up to nearest 0.5
A3: 30 | B3: From J1 to Switches (6+24) | C3: TSP | D3: 6 | E3: =A3+6+(A3*0.03) -> 36.9 | F3: =(D3*E3) -> 221.4 | G3: =_xlfn.CEILING.MATH((F3)/12,0.5,0.5) -> 18.5
A4: 16 | B4: From: P1 to J1 | C4: Hook up | D4: 2 | E4: =A4+6+(A4*0.03) -> 22.48 | F4: =(D4*E4) -> 44.96 | G4: =_xlfn.CEILING.MATH((F4)/12,0.5,0.5) -> 4
A5: 21 | B5: =A5+(A5*0.03) -> 21.63 | C5: shrink | D5: 5 | E5: =A5+6+(A5*0.03) -> 27.63 | F5: =(D5*E5) -> 138.15 | G5: =_xlfn.CEILING.MATH((F5)/12,0.5,0.5) -> 12 | H5: 1
G7: =SUM(G3:G5) -> 34.5

Sheet Bundle Factors
A1: Number of Wires | B1: Provided Data | C1: Computed Data
A2: 1 | B2: 1 | C2: 1
A3: 2 | B3: 2 | C3: =1.2038*POWER(A3,0.5033) -> 1.7063289
A4: 3 | B4: 2.2 | C4: =1.2038*POWER(A4,0.5033) -> 2.0926156
A5: 4 | B5: 2.4 | C5: =1.2038*POWER(A5,0.5033) -> 2.4186395
A6: 5 | B6: 2.7 | C6: =1.2038*POWER(A6,0.5033) -> 2.7061131
A7: 6 | B7: 2.9 | C7: =1.2038*POWER(A7,0.5033) -> 2.9661825
A8: 7 | B8: 3 | C8: =1.2038*POWER(A8,0.5033) -> 3.2054734
A9: 8 | B9: 3.3 | C9: =1.2038*POWER(A9,0.5033) -> 3.4283056
A10: 9 | B10: 3.8 | C10: =1.2038*POWER(A10,0.5033) -> 3.6376809
A11: 10 | B11: 4 | C11: =1.2038*POWER(A11,0.5033) -> 3.8357857
A12: 11 | C12: =1.2038*POWER(A12,0.5033) -> 4.0242715
A13: 12 | B13: 4.3 | C13: =1.2038*POWER(A13,0.5033) -> 4.2044216
A14: 13 | C14: =1.2038*POWER(A14,0.5033) -> 4.3772568
A15: 14 | B15: 4.6 | C15: =1.2038*POWER(A15,0.5033) -> 4.5436051
A16: 15 | C16: =1.2038*POWER(A16,0.5033) -> 4.704149
A17: 16 | B17: 5 | C17: =1.2038*POWER(A17,0.5033) -> 4.859459
A18: 17 | C18: =1.2038*POWER(A18,0.5033) -> 5.0100179
A19: 18 | B19: 5.3 | C19: =1.2038*POWER(A19,0.5033) -> 5.1562384
A20: 19 | C20: =1.2038*POWER(A20,0.5033) -> 5.2984767
A21: 20 | B21: 5.6 | C21: =1.2038*POWER(A21,0.5033) -> 5.4370426
A22: 21 | C22: =1.2038*POWER(A22,0.5033) -> 5.5722079
A23: 22 | C23: =1.2038*POWER(A23,0.5033) -> 5.7042122
A24: 23 | C24: =1.2038*POWER(A24,0.5033) -> 5.8332684
A25: 24 | C25: =1.2038*POWER(A25,0.5033) -> 5.9595663
A26: 25 | C26: =1.2038*POWER(A26,0.5033) -> 6.0832763
A27: 26 | C27: =1.2038*POWER(A27,0.5033) -> 6.2045519
A28: 27 | C28: =1.2038*POWER(A28,0.5033) -> 6.323532
A29: 28 | B29: 6.5 | C29: =1.2038*POWER(A29,0.5033) -> 6.4403427
A30: 29 | C30: =1.2038*POWER(A30,0.5033) -> 6.5550989
A31: 30 | C31: =1.2038*POWER(A31,0.5033) -> 6.667906
A32: 31 | C32: =1.2038*POWER(A32,0.5033) -> 6.7788602
A33: 32 | B33: 6.9 | C33: =1.2038*POWER(A33,0.5033) -> 6.8880505
A34: 33 | C34: =1.2038*POWER(A34,0.5033) -> 6.9955587
A35: 34 | C35: =1.2038*POWER(A35,0.5033) -> 7.1014605
A36: 35 | C36: =1.2038*POWER(A36,0.5033) -> 7.2058262
A37: 36 | B37: 7.4 | C37: =1.2038*POWER(A37,0.5033) -> 7.3087211
A38: 37 | C38: =1.2038*POWER(A38,0.5033) -> 7.4102058
A39: 38 | C39: =1.2038*POWER(A39,0.5033) -> 7.510337
A40: 39 | C40: =1.2038*POWER(A40,0.5033) -> 7.6091677
...
